Workbook

Sheet Read Me
A1: Adroit Dashboards — Report Field Requirements
A2: Which Zoho Creator report fields each dashboard needs, and why.
A5: What this is for
B6: Every dashboard reads plain Creator reports. A field that is not on the report never reaches the widget — the number silently reads as zero and the drill-down modal shows a blank column. This workbook lists every field each dashboard needs so the reports can be corrected in one pass.
A8: How to use it
B9: 1. Open the 'Report Fields' sheet and filter by Dashboard, or by Status = VERIFY.
B10: 2. For each report, open it in the Creator app builder and confirm the listed fields are on the report's columns.
B11: 3. Fields marked ADD are new — they were introduced so the drill-down modal can show a useful, identifiable record. Add them to the report.
B12: 4. Fields marked VERIFY are inferred link names. Confirm each one, and correct the CFG block at the top of the dashboard's .js file if it differs.
B13: 5. Production only: open the 'Production Not-Connected' sheet for the panels that had no Deluge function behind them at all, and what each would need to go live.
B14: 6. See the "Broken Reports" sheet for report link names that fail to load outright (wrong name, or a scan that's gone stale) — these need fixing in the Creator app builder before anything downstream can be confirmed.
B15: 7. See the "Timeline Logic" sheet for weekly/monthly/yearly boundary issues (e.g. a chart comparing the wrong pair of years) — one is already fixed, one (which day the week starts on) needs your decision.
A17: Checking it live, without this spreadsheet
B18: Every dashboard has a small "Fields" button in the top-right corner. Click it for a modal listing every report it reads, the real field names Creator returned, and a sample record per report — no DevTools needed. Use "Copy all as text" to paste the whole thing back for review.
B19: Prefer the console? Press F12 and read it directly: every report fetch prints a collapsed group with the report name, the field list sent, the record count, and the field names that actually came back. A report that returns nothing is printed in amber; one that failed, in red.
B20: Type copy(AK.reportText()) to put that table on the clipboard, ready to paste.
B21: Click any number on any dashboard to open the records behind it. The same records are logged to the console, so a wrong number can be traced to the exact rows that produced it.
A23: Status legend
A24: Confirmed | B24: The link name is verified — either used by working code or cross-checked against another dashboard reading the same form.
A25: VERIFY | B25: Inferred. Check it against the app before go-live.
A26: ADD | B26: A new field introduced this round, so drill-down modals show identifiable records. Add it to the report's columns.
A27: BROKEN | B27: The report link name does not resolve in Creator (a live scan returned an error, not just "no records"). See the "Broken Reports" sheet.
A28: STALE / UNSCANNED | B28: Either the report name changed after the last scan, or the scan never reached this report. See the "Broken Reports" sheet.
A29: REMOVED | B29: The report was dropped from the code this session because it didn't exist; a working field on a different, already-used report now does the same job.
A31: Needed for legend
A32: Calculation | B32: The number on screen cannot be computed without this field.
A33: Drill-down | B33: The number computes fine, but the record modal shows this as a column.
A34: Both | B34: Used by the calculation and shown in the modal.

Sheet Dashboards
A1: Dashboard | B1: Department | C1: Folder | D1: Entry point | E1: Data source | F1: Reports used | G1: Fields listed | H1: Drill-downs | I1: Items to verify | J1: Notes
A2: servicePerformanceSummary | B2: Service | C2: service/servicePerformanceSummary | D2: app/widget.html + app/servicePerformance.js | E2: Reports (ZOHO.CREATOR.DATA.getRecords) | F2: =SUMIF('Report Fields'!$A$2:$A$2000,$A2,'Report Fields'!$I$2:$I$2000) -> 17 | G2: =COUNTIF('Report Fields'!$A$2:$A$2000,$A2) -> 81 | H2: =COUNTIF('Drill-downs'!$A$2:$A$500,$A2) -> 39 | I2: =COUNTIFS('Report Fields'!$A$2:$A$2000,$A2,'Report Fields'!$G$2:$G$2000,"VERIFY") -> 1 | J2: CONVERTED this round from a React/Vite app to a plain JS widget. Three tabs, loaded lazily.
A3: serviceOverview | B3: Service | C3: service/serviceOverview | D3: app/widget.html + app/script.js | E3: Reports (getRecords, record_cursor, field_config: all) | F3: =SUMIF('Report Fields'!$A$2:$A$2000,$A3,'Report Fields'!$I$2:$I$2000) -> 17 | G3: =COUNTIF('Report Fields'!$A$2:$A$2000,$A3) -> 50 | H3: =COUNTIF('Drill-downs'!$A$2:$A$500,$A3) -> 20 | I3: =COUNTIFS('Report Fields'!$A$2:$A$2000,$A3,'Report Fields'!$G$2:$G$2000,"VERIFY") -> 3 | J3: Retrofitted: number formatting, drill-downs, fetch logging, no-records states. Was the one dashboard still on the v1 SDK / ZOHO.CREATOR.API.getAllRecords(); switched to v2 / DATA.getRecords() to match every other dashboard.
A4: salesExecutiveCommandView | B4: Sales | C4: sales/salesExecutiveCommandView | D4: app/widget.html + app/script.js | E4: Reports (getRecords, record_cursor, field_config: all) | F4: =SUMIF('Report Fields'!$A$2:$A$2000,$A4,'Report Fields'!$I$2:$I$2000) -> 12 | G4: =COUNTIF('Report Fields'!$A$2:$A$2000,$A4) -> 39 | H4: =COUNTIF('Drill-downs'!$A$2:$A$500,$A4) -> 7 | I4: =COUNTIFS('Report Fields'!$A$2:$A$2000,$A4,'Report Fields'!$G$2:$G$2000,"VERIFY") -> 8 | J4: Uses field_config 'all', so no field list is sent — the fields below are the ones the code reads.
A5: salesPerformanceSummary | B5: Sales | C5: sales/sales_performance_summary | D5: app/widget.html + app/salesPerformance.js | E5: Reports (getRecords, field_config: custom) | F5: =SUMIF('Report Fields'!$A$2:$A$2000,$A5,'Report Fields'!$I$2:$I$2000) -> 21 | G5: =COUNTIF('Report Fields'!$A$2:$A$2000,$A5) -> 74 | H5: =COUNTIF('Drill-downs'!$A$2:$A$500,$A5) -> 14 | I5: =COUNTIFS('Report Fields'!$A$2:$A$2000,$A5,'Report Fields'!$G$2:$G$2000,"VERIFY") -> 0 | J5: Sends an explicit field list; a field missing from the report simply never arrives.
A6: salesKPIDashboard | B6: Sales | C6: sales/salesKPIDashboard | D6: app/widget.html + app/salesKPI.js | E6: Reports (getRecords, field_config: custom) | F6: =SUMIF('Report Fields'!$A$2:$A$2000,$A6,'Report Fields'!$I$2:$I$2000) -> 8 | G6: =COUNTIF('Report Fields'!$A$2:$A$2000,$A6) -> 40 | H6: =COUNTIF('Drill-downs'!$A$2:$A$500,$A6) -> 15 | I6: =COUNTIFS('Report Fields'!$A$2:$A$2000,$A6,'Report Fields'!$G$2:$G$2000,"VERIFY") -> 13 | J6: CONVERTED this round from the Get_KPI_Dashboard_Data Custom API. Most rules below are inferred — see the To Verify sheet.
A7: storeToday | B7: Store | C7: Store/storeToday | D7: app/widget.html + app/storeToday.js | E7: Reports (getRecords, field_config: custom) | F7: =SUMIF('Report Fields'!$A$2:$A$2000,$A7,'Report Fields'!$I$2:$I$2000) -> 4 | G7: =COUNTIF('Report Fields'!$A$2:$A$2000,$A7) -> 30 | H7: =COUNTIF('Drill-downs'!$A$2:$A$500,$A7) -> 11 | I7: =COUNTIFS('Report Fields'!$A$2:$A$2000,$A7,'Report Fields'!$G$2:$G$2000,"VERIFY") -> 4 | J7: CONVERTED this round from the todayStoreWidget Custom API. Most rules below are inferred — see the To Verify sheet.
A8: storeWeekly | B8: Store | C8: Store/storeWeekly | D8: app/widget.html + app/storeWeekly.js | E8: Reports (getRecords, field_config: custom) | F8: =SUMIF('Report Fields'!$A$2:$A$2000,$A8,'Report Fields'!$I$2:$I$2000) -> 4 | G8: =COUNTIF('Report Fields'!$A$2:$A$2000,$A8) -> 21 | H8: =COUNTIF('Drill-downs'!$A$2:$A$500,$A8) -> 9 | I8: =COUNTIFS('Report Fields'!$A$2:$A$2000,$A8,'Report Fields'!$G$2:$G$2000,"VERIFY") -> 0 | J8: Retrofitted: drill-downs, fetch logging, no-records states.
A9: storeMonthly | B9: Store | C9: Store/storeMonthly | D9: app/widget.html + app/monthlyStore.js | E9: Reports (getRecords, field_config: custom) | F9: =SUMIF('Report Fields'!$A$2:$A$2000,$A9,'Report Fields'!$I$2:$I$2000) -> 7 | G9: =COUNTIF('Report Fields'!$A$2:$A$2000,$A9) -> 29 | H9: =COUNTIF('Drill-downs'!$A$2:$A$500,$A9) -> 14 | I9: =COUNTIFS('Report Fields'!$A$2:$A$2000,$A9,'Report Fields'!$G$2:$G$2000,"VERIFY") -> 14 | J9: Retrofitted: drill-downs, fetch logging, no-records states.
A10: storeYearly | B10: Store | C10: Store/storeYearly | D10: app/widget.html + app/yearlyStore.js | E10: Reports (getRecords, field_config: custom) | F10: =SUMIF('Report Fields'!$A$2:$A$2000,$A10,'Report Fields'!$I$2:$I$2000) -> 10 | G10: =COUNTIF('Report Fields'!$A$2:$A$2000,$A10) -> 29 | H10: =COUNTIF('Drill-downs'!$A$2:$A$500,$A10) -> 8 | I10: =COUNTIFS('Report Fields'!$A$2:$A$2000,$A10,'Report Fields'!$G$2:$G$2000,"VERIFY") -> 6 | J10: Retrofitted: drill-downs, fetch logging, no-records states.
A11: productionOverview | B11: Production | C11: Production/productionOverview | D11: app/widget.html + app/productionOverview.js | E11: Reports (getRecords, field_config: custom) | F11: =SUMIF('Report Fields'!$A$2:$A$2000,$A11,'Report Fields'!$I$2:$I$2000) -> 6 | G11: =COUNTIF('Report Fields'!$A$2:$A$2000,$A11) -> 20 | H11: =COUNTIF('Drill-downs'!$A$2:$A$500,$A11) -> 10 | I11: =COUNTIFS('Report Fields'!$A$2:$A$2000,$A11,'Report Fields'!$G$2:$G$2000,"VERIFY") -> 1 | J11: CONVERTED this round from a Zoho Creator Deluge HTML snippet. 8 panels have a real Deluge function behind them (one — Today's & Weekly Overview — existed in the Deluge source with real logic but was never wired into the original page; wired in now). The rest (roughly two thirds of the page) was 100% hardcoded demo numbers with no data source at all and is shown as 'Not connected' rather than invented — cross-checked against dashboard_docs/Production_Dashboard.docx, see the Production Not-Connected sheet.

Sheet Broken Reports
A1: Reports that fail to load — found via the live "Fields" scan
A2: Every row below is a report link name that Creator rejected, or one whose scan is now stale/incomplete. Nothing here is a guess — each status is the exact response from a live discoverFields() scan run against the current app. Fix the ones marked BROKEN or STALE in the Creator app builder, then correct CFG.reports in the dashboard's .js file if the real name differs.
A4: Dashboard | B4: Report (link name) | C4: Live scan result | D4: What this breaks | E4: Recommended action | F4: Status
A5: storeMonthly | B5: Purchase_Order_Register | C5: code 2930: "Error Occurred." — report does not resolve. | D5: Vendor "delivered late" detection in the Vendor Performance table always read as clean (only caught "still overdue", never "delivered but late"). | E5: Already fixed in code this session: the report was removed and replaced with the Delivered_On field, which already exists on All_Purchase_Orders. No action needed unless you want a dedicated register report. | F5: FIXED
A6: storeMonthly | B6: All_Tools | C6: Not included in the fields.txt scan — never tested. | D6: Tools/risk fields used by this dashboard are unconfirmed. | E6: Reload the dashboard, click "Fields" (top-right), then "Copy all as text", and resend so this report gets scanned. | F6: UNSCANNED
A7: storeYearly | B7: Purchase_Order_Register | C7: code 2930: "Error Occurred." — report does not resolve. | D7: Same as storeMonthly: 3 avg-lead-time calculations (annual summary, tile section, year-over-year) plus their own drill-down all read as empty/zero. | E7: Already fixed in code this session: removed, replaced with Delivered_On on All_Purchase_Orders. No action needed unless you want a dedicated register report. | F7: FIXED
A8: storeYearly | B8: All_Scrap | C8: code 2894: "No report named All_Scrap found." | D8: The annual scrap-value trend (one of two scrap-value definitions this dashboard computes) always reads 0 for all 3 years. | E8: Find the real report link name for the Scrap form in the Creator app builder, then update CFG.reports.scrap in yearlyStore.js. | F8: BROKEN
A9: storeYearly | B9: All_Service_Executive | C9: code 2894: "No report named All_Service_Executive found." | D9: The "Risk Mitigations Implemented" figure (already shown as N/A on screen, per the original HTML) always computes as 0. | E9: Find the real report link name in the Creator app builder, then update CFG.reports.serviceExecutive in yearlyStore.js. | F9: BROKEN
A10: productionOverview | B10: Add_Work_Order_SERVO | C10: code 2930: "Error Occurred." — report does not resolve. | D10: Weekly/Monthly/Yearly Planned vs Actual Production charts AND the Today's & Weekly Overview panel (delays, rework, man-hours) all read empty — most of this dashboard's "real, data-backed" panels. | E10: Every other confirmed report in this app follows an "All_<Form>" naming convention; this one is "Add_<Form>", which looks like a Deluge add-form link rather than a report link. Try "All_Work_Order_SERVO" in the app builder — click "Fields" to test it live before trusting it. | F10: BROKEN
A11: productionOverview | B11: All_Reworks | C11: code 9220: "No records exist in this report." — the name IS valid, it is just empty. | D11: Weekly/Monthly/Yearly Rework Trend charts are always empty. | E11: Confirm with whoever owns the Production app: is Production rework genuinely a separate, currently-empty log, or should this point at All_Rework_Registers instead (the same-sounding report the Store dashboards use, which DOES have records)? | F11: EMPTY — CONFIRM
A12: productionOverview | B12: All_Rejection_Modules | C12: The live scan tested the singular "All_Rejection_Module" and got code 2894 (not found). The report name in the code was changed to plural afterward — that change has never been tested. | D12: Rejection-related figures — unconfirmed either way right now. | E12: Click "Fields" on the dashboard and rescan to find out whether the plural name actually resolves. | F12: STALE — RESCAN
A13: productionOverview | B13: All_Preventive_Maintenances | C13: The live scan tested the singular "All_Preventive_Maintenance" and got code 2894 (not found). The report name in the code was changed to plural afterward — that change has never been tested. | D13: Maintenance table + compliance % — unconfirmed either way right now. | E13: Click "Fields" on the dashboard and rescan to find out whether the plural name actually resolves. | F13: STALE — RESCAN
A14: salesExecutiveCommandView | B14: 8 of 12 reports (QUOTATION_FOLLOW_UP, CALLING_FOLLOW_UP, ORDER_LOST, SERVICE_FEEDBACK, CUSTOMER_ADDRESS, CUSTOMER, ABC_CONFIG, and QUOTATION only partially) | C14: The fields.txt you sent was copied before the sequential scan of all 12 reports finished — only the first 4 came through. | D14: Can't confirm those reports' field names against real data yet. | E14: Let the dashboard fully load, click "Fields" -> "Copy all as text" again (give it a minute to finish scanning all 12 reports this time), and resend. | F14: UNSCANNED

Sheet Timeline Logic
A1: Weekly / monthly / yearly boundary logic — checked across all 10 dashboards
A2: Triggered by the "2025 vs 2024" bug on Sales Performance Summary — with today's date in 2026, that chart was comparing the previous two COMPLETE years and silently excluding the current year entirely. Every dashboard was swept for the same class of issue: hardcoded years, "skip the current period" patterns, and inconsistent week/month/year boundaries. Two things found — one fixed outright, one that needs your call since it's a real business-rule question, not a typo.
A4: Dashboard | B4: Panel / function | C4: What it did | D4: What changed / what's needed | E4: Confirm? | F4: Status
A5: sales_performance_summary | B5: Monthly Sales Revenue Trend chart (getPreviousYearsMonthlyRevenue) | C5: Computed "current year - 1" and "current year - 2" — e.g. with today in 2026, it plotted 2025 vs 2024 and never looked at 2026 at all. That's why the chart was empty in the screenshot: it wasn't broken, it just never asked for the year you were looking at. | D5: FIXED — now computes "current year" (2026, partial, through today) vs "previous year" (2025). Future months of the current year read as 0 until real orders land, which is correct for a partial year. | E5: No — already corrected. | F5: FIXED
A6: Week start day — cross-dashboard | B6: Every "this week" / weekly-trend calculation | C6: Three different conventions were in use, inconsistently: servicePerformanceSummary and sales_performance_summary started the week Monday; productionOverview started it Sunday; storeWeekly used BOTH in the same dashboard (Monday for material flow/rejection/issued-vs-returned, Sunday for the "Week 1"-"Week 4" rework expense trend). | D6: FIXED — standardized on Monday everywhere (ISO 8601 + standard Indian business week, Mon-Sat with Sunday off), matching the two dashboards that already used it. productionOverview's startOfWeek() and storeWeekly's rework-expense trend both switched from Sunday-start to Monday-start. | E6: No — already corrected. | F6: FIXED
A7: All 10 dashboards | B7: Hardcoded year/date literals | C7: Checked for any literal "2024"/"2025"/"2026" used in actual date logic (not comments or format examples). | D7: None found — every other date boundary in every dashboard computes from today's real date (new Date()), not a fixed year. Only the one row above had a logic issue, not a hardcoded value. | E7: No action needed. | F7: CLEAN
A8: All 10 dashboards | B8: Month-length / leap-year arithmetic | C8: Checked for any hand-rolled "30 or 31 days" math instead of native Date rollover. | D8: None found — every start/end-of-month calculation uses new Date(year, month+1, 0)-style native rollover, which handles December→January and leap-year February correctly on its own. | E8: No action needed. | F8: CLEAN
A9: All 10 dashboards | B9: "Last N months/years" rolling windows | C9: Spot-checked every trailing-window trend (18-month lead time, 6-month non-moving stock, 5-year annual summary, 3-year performance summary, etc.) for the same "excludes the current period" bug as the row above. | D9: All of these correctly include the current, in-progress period at offset 0 — only the yearly revenue trend had the bug. | E9: No action needed. | F9: CLEAN

Sheet Report Fields
A1: Dashboard | B1: Report (link name) | C1: Field (link name) | D1: Subform | E1: Used for | F1: Needed for | G1: Status | H1: Notes | I1: New report?
A2: servicePerformanceSummary | B2: Service_Call_Logs | C2: Date_field | E2: Date the call was logged — every period filter | F2: Both | G2: Confirmed | I2: 1
A3: servicePerformanceSummary | B3: Service_Call_Logs | C3: Status | E3: Completed / Pending / Draft splits | F3: Both | G3: Confirmed | I3: 0
A4: servicePerformanceSummary | B4: Service_Call_Logs | C4: Customer_Name | E4: Repeat-call grouping (customers with 2+ calls) | F4: Both | G4: Confirmed | H4: Lookup | I4: 0
A5: servicePerformanceSummary | B5: Service_Call_Logs | C5: Service_Engineer_Name | E5: Engineer-wise call volume | F5: Both | G5: Confirmed | H5: Lookup | I5: 0
A6: servicePerformanceSummary | B6: Service_Call_Logs | C6: Nature_Of_Calls | E6: Warranty / PW / AMC split, invoice trend | F6: Both | G6: Confirmed | I6: 0
A7: servicePerformanceSummary | B7: Service_Call_Logs | C7: Repeat_Call_Reason | E7: Repeat-call reason pie | F7: Both | G7: Confirmed | I7: 0
A8: servicePerformanceSummary | B8: Service_Call_Logs | C8: Service_Call_Log_No | E8: Matches invoices to calls; shown as the modal's first column | F8: Both | G8: Confirmed | I8: 0
A9: servicePerformanceSummary | B9: All_Service_Reports | C9: Call_Attended_Date | E9: Reports submitted today, red tag trend, stock delays | F9: Both | G9: Confirmed | I9: 1
A10: servicePerformanceSummary | B10: All_Service_Reports | C10: Call_Received_Date | E10: Average response time | F10: Calculation | G10: Confirmed | I10: 0
A11: servicePerformanceSummary | B11: All_Service_Reports | C11: Service_Call_Log | E11: Links a report to its call log | F11: Both | G11: Confirmed | H11: Lookup | I11: 0
A12: servicePerformanceSummary | B12: All_Service_Reports | C12: Service_Engineer_Name | E12: Executive performance bars | F12: Both | G12: Confirmed | H12: Lookup | I12: 0
A13: servicePerformanceSummary | B13: All_Service_Reports | C13: Status | E13: Completed / Pending For Spares | F13: Both | G13: Confirmed | I13: 0
A14: servicePerformanceSummary | B14: All_Service_Reports | C14: Product | E14: Red tag item trend | F14: Both | G14: Confirmed | H14: Lookup | I14: 0
A15: servicePerformanceSummary | B15: All_Service_Reports | C15: Added_Time | E15: Complaint cost by category window | F15: Calculation | G15: Confirmed | I15: 0
A16: servicePerformanceSummary | B16: All_Service_Reports | C16: Spare_Replaced | D16: Spare_Replaced | E16: Subform holding the spare lines | F16: Calculation | G16: Confirmed | H16: Subform | I16: 0
A17: servicePerformanceSummary | B17: All_Service_Reports | C17: Date_field | D17: Spare_Replaced | E17: Date of each spare line | F17: Both | G17: Confirmed | H17: Subform field | I17: 0
A18: servicePerformanceSummary | B18: All_Service_Reports | C18: Nature_of_Calls | D18: Spare_Replaced | E18: AMC / PW / Warranty split of complaint cost | F18: Both | G18: Confirmed | H18: Subform field | I18: 0
A19: servicePerformanceSummary | B19: All_Service_Feedback1 | C19: Company_Name | E19: Every feedback metric requires a customer | F19: Both | G19: Confirmed | H19: Lookup | I19: 1
A20: servicePerformanceSummary | B20: All_Service_Feedback1 | C20: Rating | E20: Satisfaction, regret cases, positive feedback % | F20: Both | G20: Confirmed | I20: 0
A21: servicePerformanceSummary | B21: All_Service_Feedback1 | C21: Call_attended_date | E21: Period filter for all feedback metrics | F21: Both | G21: Confirmed | I21: 0
A22: servicePerformanceSummary | B22: All_Service_Feedback1 | C22: Any_additional_comments_or_suggestions_would_be_appreciated1 | E22: Recent complaints / recent feedback text | F22: Both | G22: Confirmed | I22: 0
A23: servicePerformanceSummary | B23: All_Service_Feedback1 | C23: service_engineer_attended_the_call | E23: Shows who attended, in the feedback modal | F23: Drill-down | G23: ADD | H23: Add to the report's columns if not already there | I23: 0
A24: servicePerformanceSummary | B24: Field_Executives | C24: Date_field | E24: Executives active today, weekly Google reviews | F24: Both | G24: Confirmed | I24: 1
A25: servicePerformanceSummary | B25: Field_Executives | C25: Leave_Break | E25: Excludes Emergency / Informed Leave | F25: Both | G25: Confirmed | I25: 0
A26: servicePerformanceSummary | B26: Field_Executives | C26: Employee_Name | E26: Google review count requires a named employee | F26: Both | G26: Confirmed | I26: 0
A27: servicePerformanceSummary | B27: Field_Executives | C27: Did_you_collect_google_rating | E27: Weekly Google review collection | F27: Both | G27: Confirmed | I27: 0
A28: servicePerformanceSummary | B28: All_Employees | C28: Employee_Name | E28: Engineer labels on every per-engineer chart | F28: Both | G28: Confirmed | I28: 1
A29: servicePerformanceSummary | B29: All_Employees | C29: Department_Role | E29: Identifies service engineers | F29: Calculation | G29: Confirmed | H29: Matched against SERVICE_DEPARTMENT_ROLE_ID = 302392000000624113. Confirm this record ID is still right. | I29: 0
A30: servicePerformanceSummary | B30: Service_Quotations | C30: Date_field | E30: AMC analytics window | F30: Both | G30: Confirmed | I30: 1
A31: servicePerformanceSummary | B31: Service_Quotations | C31: Status | E31: Quotations Sent Today | F31: Both | G31: Confirmed | I31: 0
A32: servicePerformanceSummary | B32: Service_Quotations | C32: Customer_Name | E32: AMC quotations require a customer | F32: Both | G32: Confirmed | H32: Lookup | I32: 0
A33: servicePerformanceSummary | B33: Service_Quotations | C33: Nature_of_Calls | E33: Picks out AMC quotations | F33: Both | G33: Confirmed | I33: 0
A34: servicePerformanceSummary | B34: Service_Quotations | C34: Service_Quotation_No | E34: First column of the quotation modal | F34: Drill-down | G34: Confirmed | H34: Corrected this session — "Quotation_Number" does not exist on Service_Quotations; the real field is "Service_Quotation_No". | I34: 0
A35: servicePerformanceSummary | B35: Service_Invoice_Follow_up_Un_paid | C35: Date_field | E35: Invoices generated today | F35: Both | G35: Confirmed | I35: 1
A36: servicePerformanceSummary | B36: Service_Invoice_Follow_up_Un_paid | C36: Customer | E36: An invoice only counts when it names a customer | F36: Both | G36: Confirmed | H36: Lookup | I36: 0
A37: servicePerformanceSummary | B37: Service_Invoice_Follow_up_Un_paid | C37: Final_Total | E37: Invoice amount tile and AMC/Install/Repair trend | F37: Both | G37: Confirmed | I37: 0
A38: servicePerformanceSummary | B38: Service_Invoice_Follow_up_Un_paid | C38: Spare_Amount | E38: Spares column of the invoice trend | F38: Both | G38: Confirmed | I38: 0
A39: servicePerformanceSummary | B39: Service_Invoice_Follow_up_Un_paid | C39: Service_Amount | E39: Service column of the invoice trend | F39: Both | G39: Confirmed | I39: 0
A40: servicePerformanceSummary | B40: Service_Invoice_Follow_up_Un_paid | C40: Service_Call_Log | E40: Maps an invoice to a call's Nature of Calls | F40: Both | G40: Confirmed | H40: Lookup | I40: 0
...

Sheet Drill-downs
A1: Dashboard | B1: Tab / Section | C1: Number on screen | D1: Source report | E1: Filter the modal applies | F1: Columns the modal shows
A2: servicePerformanceSummary | B2: Today | C2: Total Calls Logged Today | D2: Service_Call_Logs | E2: Date_field = today | F2: Call No, Date, Customer, Engineer, Nature, Status, Repeat Reason
A3: servicePerformanceSummary | B3: Today | C3: Service Executives Active Today | D3: Field_Executives | E3: Date_field = today AND Leave_Break not in (Emergency Leave, Informed Leave) | F3: Date, Employee, Leave/Break, Google Rating Collected
A4: servicePerformanceSummary | B4: Today | C4: Service Reports Submitted | D4: All_Service_Reports | E4: Call_Attended_Date = today AND its Service_Call_Log is Completed (each call once) | F4: Call Log, Attended, Received, Engineer, Product, Status
A5: servicePerformanceSummary | B5: Today | C5: Quotations Sent Today | D5: Service_Quotations | E5: Date_field = today AND Status = Sent | F5: Quotation No, Date, Customer, Nature, Status
A6: servicePerformanceSummary | B6: Today | C6: Customer Feedbacks Collected | D6: All_Service_Feedback1 | E6: Call_attended_date = today AND Company_Name is filled | F6: Date, Customer, Engineer, Rating, Comments
A7: servicePerformanceSummary | B7: Today | C7: Pending Calls > 48 Hrs | D7: Service_Call_Logs | E7: Status = Pending AND Date_field <= today - 2 | F7: Call No, Date, Customer, Engineer, Nature, Status
A8: servicePerformanceSummary | B8: Today | C8: Customer Regret Cases | D8: All_Service_Feedback1 | E8: Rating = 2 (any date) OR Rating = 1 today — the original Deluge precedence, kept | F8: Date, Customer, Engineer, Rating, Comments
A9: servicePerformanceSummary | B9: Today | C9: Repeat Calls Logged | D9: Service_Call_Logs | E9: Pending calls today for customers with 2 or more such calls | F9: Call No, Date, Customer, Engineer, Nature, Status
A10: servicePerformanceSummary | B10: Today | C10: Invoices Generated Today / Invoice Amounts | D10: Service_Invoice_Follow_up_Un_paid | E10: Date_field = today AND Customer is filled | F10: Invoice No, Date, Customer, Call Log, Service Amt, Spare Amt, Final Total
A11: servicePerformanceSummary | B11: Today | C11: Invoice Amount Trend (AMC / Install / Repair / Service / Spares) | D11: Service_Invoice_Follow_up_Un_paid | E11: Today's invoices bucketed by their call's Nature_Of_Calls | F11: Invoice No, Date, Customer, Call Log, amounts
A12: servicePerformanceSummary | B12: Today | C12: Repeat Calls Reason (each slice) | D12: Service_Call_Logs | E12: Date_field = today AND Repeat_Call_Reason = the slice | F12: Call No, Date, Customer, Engineer, Repeat Reason
... A148: productionOverview | B148: Today's & Weekly Overview | C148: Man-Hours Logged (Today / This Week) | D148: Add_Work_Order_SERVO | E148: Work orders dated in that window with Man_Hours filled in | F148: Date, Status, Man Hours

Sheet Production Not-Connected
A1: Production Dashboard — panels with no data source
A2: Roughly two thirds of the original Deluge page was hardcoded demo numbers with no custom function behind them at all — not inferred, not guessed, literally typed constants like bom_accuracy = 97. Nothing was invented to fill these in: the widget shows each one as an explicit ‘Not connected to data’ panel. Column D cross-checks each one against dashboard_docs/Production_Dashboard.docx — where the doc's own “Changes required in field” section confirms a field is genuinely new (not yet in the app), that's called out explicitly.
A4: IMPORTANT — this sheet only covers panels that never had a real data source, even in the original Deluge page. It does NOT cover the separate problem found this session: 4 of the 6 reports the REAL, code-backed panels above depend on (Weekly/Monthly/Yearly Planned vs Actual Production, Rework Trend, the Maintenance table) currently fail or return nothing when read from Zoho. See the "Broken Reports" sheet for those — they are fixable by correcting a report link name, not by building anything new.
A6: Panel | B6: What the original showed | C6: What it would need to become real | D6: Per the spec doc
A7: Customer Complaints tile | B7: Hardcoded literal "N/A" | C7: A complaint-logging report with a date and a production-related flag | D7: Confirmed NEW field — doc: “customer complaint due to production like wiring loose connection, Quality check”
A8: Complaint Types Breakdown (pie) | B8: wiring/finish/other percentages hardcoded to 0 — permanently an empty pie even in the original | C8: Complaint records categorised by type (Wiring Loose / Finish Issue / Other — doc's own category names) | D8: Same complaint log as the tile above
A9: Material, BOM & Inventory Control tiles | B9: 4 tiles, all literal numbers (Production Stops, Inventory Value, Red-Tag count, Parts Awaiting) | C9: Production-stoppage log; stock valuation report; a material-request/backorder report | D9: Production Stops confirmed NEW field — doc: “if there any production stop or production delay due to non-availability of item”. Inventory Value target < ₹5L per the doc (a different figure, “red if >₹50k”, appears elsewhere in the same doc — worth asking which is right).
A10: Material Shortage Impact (weekly/monthly/yearly) | B10: 12 bars, all literal numbers reused across all three tabs | C10: A function called getMaterialShortageImpackWeekly() exists but actually computes planned work-order counts (duplicates the Production Performance panel) — it does not compute shortages, and the page never called it | D10: Doc wants a “Material Shortage Trend – Line chart” but doesn't name a source either
A11: This Month Products & Indirect Expenses table | B11: 3 hardcoded demo rows (ORD-1205/1206/1207) | C11: A per-order cost/expense report: man-hours cost, freight, packing, other, joined to Order Confirmation | D11: Doc gives exact columns: Order No, Product, Man-Hours, Labour Cost, Transport, Cutting, Powder Coating, Other Outsource, Total Indirect Cost, % of Order Value. Man-Hours is now real (Today's & Weekly Overview panel) — the rest is a confirmed NEW field per the doc's fabricator/cutting/coating note.
A12: Inventory & Material tiles | B12: 3 hardcoded values (Holding Days, Inventory Value, Material Shortages) | C12: Same stock valuation source as the Material/BOM panel above | D12: Doc targets: Holding Days < 30 (red if > 65); Material Shortages 0 orders affected (alert if > 0)
A13: Improvement, Training & Risk Management table | B13: 6 hardcoded rows | C13: A Kaizen/Six Sigma log, a training log with expenses, a risk register | D13: Confirmed NEW fields — doc: “Six sigma and Kaizen include as field as well KPI for individual” and “Internal and external training for production people given or not and expenses for the same”
A14: Improvements Implemented vs Cost Savings chart | B14: Hardcoded per-month counts and cost-saving amounts | C14: Same Kaizen/improvement log as above, with a cost-saving amount per entry | D14: See row above
A15: KPI Performance Trend — On-Time Delivery (3 months) [NOW LIVE] | B15: Hardcoded 50% / 93% / 95% | C15: DONE this session — calcMonthlyOnTimeTrend() computes real On-Time % for the last 3 months from All_Order_Confirmations, same logic as the weekly trend above. Click any point to drill into the orders behind it. | D15: The doc wants 2 more lines here (BOM Accuracy %, Rework %) — still blocked, no data source exists for either yet.
A16: Individual KPI & Team Evaluation table | B16: 11 hardcoded rows | C16: A per-metric target/current pair — several (rework %, maintenance compliance %) already have a real source elsewhere on this dashboard and just need pulling into this table; the rest need their own source | D16: Confirmed NEW form needed — doc: “individual performance report submitted for each production people by the head (KPI as well as should be added in the field)”

Sheet To Verify
A1: Everything that still needs your confirmation
A2: Each row is a link name or a business rule that was inferred rather than read from working code. Confirm it in the Creator app builder, then correct the CFG block at the top of the dashboard's .js file if it differs.
A4: Dashboard | B4: Report (link name) | C4: Field / rule | D4: Why it matters | E4: Status | F4: Confirmed? (y/n)
A5: servicePerformanceSummary | B5: All_Service_Feedback1 | C5: service_engineer_attended_the_call | D5: Add to the report's columns if not already there | E5: ADD
A6: servicePerformanceSummary | B6: Service_Quotations | C6: Service_Quotation_No | D6: Corrected this session — "Quotation_Number" doesn't exist on Service_Quotations; the real field "Service_Quotation_No" is already used in the code, nothing to add in Zoho. | E6: Confirmed | F6: y
A7: servicePerformanceSummary | B7: Service_Invoice_Follow_up_Un_paid | C7: Invoice_Number | D7: Add to the report's columns | E7: ADD
A8: servicePerformanceSummary | B8: Rejection_And_Replacement_Register_Report | C8: Defective_Product | D8: Shown in the replacement modal | E8: ADD
A9: servicePerformanceSummary | B9: Rejection_And_Replacement_Register_Report | C9: Qty | D9: Shown in the replacement modal | E9: ADD
A10: servicePerformanceSummary | B10: Stand_By_Unit1 | C10: Product | D10: Shown in the standby modal | E10: ADD
A11: servicePerformanceSummary | B11: All_Amc_Contracts | C11: Customer_Name | D11: Shown in the contract modal | E11: ADD
A12: servicePerformanceSummary | B12: All_Amc_Contracts | C12: Date_field | D12: Shown in the contract modal | E12: ADD
A13: servicePerformanceSummary | B13: All_Product | C13: Product_Code | D13: Shown in the product modal | E13: ADD
A14: servicePerformanceSummary | B14: Vehicle_Service_Reports | C14: Service_Tools_Kit_of_Engineers | D14: The original Deluge read the tool-kit subform name here. 'Report' is tried as a fallback. Confirm which one the vehicle form actually uses. | E14: VERIFY
A15: serviceOverview | B15: Service_Call_Logs | C15: Customer_Name | D15: Shown in the call log modal | E15: ADD
A16: serviceOverview | B16: Service_Quotations | C16: Customer_Name | D16: Code also tries 'Customer' | E16: VERIFY
A17: serviceOverview | B17: Service_Quotations | C17: Nature_of_Calls | D17: Code also tries 'Nature_Of_Calls' | E17: VERIFY
A18: serviceOverview | B18: Service_Quotations | C18: Date_field | D18: Code also tries Date / Quotation_Date / Added_Time | E18: VERIFY
... A110: productionOverview | B110: All_Preventive_Maintenance | C110: Type_of_Maintenance | D110: Buckets into Machine / Vehicle / Calibration by .contains() | E110: VERIFY
A111: (example) | B111: All_Purchase_Orders | C111: PO_No | D111: Fill the yellow column with y or n; add the correct link name here if it differs. | E111: VERIFY | F111: y
A113: Legend: | B113: Yellow cells are the ones to fill in. Everything else is reference.
